Workbook
Name Данные_Основной: 'Основной счет'!$1:$1048576

Sheet Основной счет
A1: date | B1: transaction_id | C1: description | D1: category | E1: type | F1: amount | G1: balance | H1: year | I1: month | J1: month_name | K1: quarter | L1: day_of_week | M1: day_of_week_num | N1: is_income | O1: is_expense | P1: calculated_balance
A2: 2022-01-01 | B2: TX00001 | C2: Daily Sales Deposit | D2: Sales Revenue | E2: Credit | F2: 802 | G2: 15802 | H2: 2022 | I2: 1 | J2: January | K2: 1 | L2: Saturday | M2: 5 | N2: TRUE | O2: FALSE | P2: 15802
A3: 2022-01-02 | B3: TX00002 | C3: Daily Sales Deposit | D3: Sales Revenue | E3: Credit | F3: 970 | G3: 16772 | H3: 2022 | I3: 1 | J3: January | K3: 1 | L3: Sunday | M3: 6 | N3: TRUE | O3: FALSE | P3: 16772
A4: 2022-01-03 | B4: TX00003 | C4: Daily Sales Deposit | D4: Sales Revenue | E4: Credit | F4: 888 | G4: 17660 | H4: 2022 | I4: 1 | J4: January | K4: 1 | L4: Monday | M4: 0 | N4: TRUE | O4: FALSE | P4: 17660
A5: 2022-01-04 | B5: TX00004 | C5: Daily Sales Deposit | D5: Sales Revenue | E5: Credit | F5: 821 | G5: 18481 | H5: 2022 | I5: 1 | J5: January | K5: 1 | L5: Tuesday | M5: 1 | N5: TRUE | O5: FALSE | P5: 18481
A6: 2022-01-04 | B6: TX00005 | C6: Utility Bill Payment | D6: Operating Expense | E6: Debit | F6: 430 | G6: 18051 | H6: 2022 | I6: 1 | J6: January | K6: 1 | L6: Tuesday | M6: 1 | N6: FALSE | O6: TRUE | P6: 18051
A7: 2022-01-05 | B7: TX00006 | C7: Daily Sales Deposit | D7: Sales Revenue | E7: Credit | F7: 787 | G7: 18838 | H7: 2022 | I7: 1 | J7: January | K7: 1 | L7: Wednesday | M7: 2 | N7: TRUE | O7: FALSE | P7: 18838
A8: 2022-01-06 | B8: TX00007 | C8: Daily Sales Deposit | D8: Sales Revenue | E8: Credit | F8: 1059 | G8: 19897 | H8: 2022 | I8: 1 | J8: January | K8: 1 | L8: Thursday | M8: 3 | N8: TRUE | O8: FALSE | P8: 19897
A9: 2022-01-07 | B9: TX00008 | C9: Daily Sales Deposit | D9: Sales Revenue | E9: Credit | F9: 849 | G9: 20746 | H9: 2022 | I9: 1 | J9: January | K9: 1 | L9: Friday | M9: 4 | N9: TRUE | O9: FALSE | P9: 20746
A10: 2022-01-07 | B10: TX00009 | C10: Rent Payment | D10: Operating Expense | E10: Debit | F10: 443 | G10: 20303 | H10: 2022 | I10: 1 | J10: January | K10: 1 | L10: Friday | M10: 4 | N10: FALSE | O10: TRUE | P10: 20303
A11: 2022-01-08 | B11: TX00010 | C11: Daily Sales Deposit | D11: Sales Revenue | E11: Credit | F11: 1113 | G11: 21416 | H11: 2022 | I11: 1 | J11: January | K11: 1 | L11: Saturday | M11: 5 | N11: TRUE | O11: FALSE | P11: 21416
A12: 2022-01-09 | B12: TX00011 | C12: Daily Sales Deposit | D12: Sales Revenue | E12: Credit | F12: 891 | G12: 22307 | H12: 2022 | I12: 1 | J12: January | K12: 1 | L12: Sunday | M12: 6 | N12: TRUE | O12: FALSE | P12: 22307
A13: 2022-01-10 | B13: TX00012 | C13: Daily Sales Deposit | D13: Sales Revenue | E13: Credit | F13: 860 | G13: 23167 | H13: 2022 | I13: 1 | J13: January | K13: 1 | L13: Monday | M13: 0 | N13: TRUE | O13: FALSE | P13: 23167
... A878: 2023-12-31 | B878: TX00877 | C878: Daily Sales Deposit | D878: Sales Revenue | E878: Credit | F878: 1141 | G878: 554608 | H878: 2023 | I878: 12 | J878: December | K878: 4 | L878: Sunday | M878: 6 | N878: TRUE | O878: FALSE | P878: 554608

Sheet Расчеты_основной
A1: Общая статистика
A2: Всего доходов | B2: =SUMIF('Основной счет'!E:E, "Credit", 'Основной счет'!F:F) -> 582807
A3: Всего расходов | B3: =SUMIF('Основной счет'!E:E, "Debit", 'Основной счет'!F:F) -> 43199
A4: Чистая прибыль | B4: =B2-B3 -> 539608
A5: Кол-во доходов | B5: =COUNTIF('Основной счет'!E:E, "Credit") -> 730
A6: Кол-во расходов | B6: =COUNTIF('Основной счет'!E:E, "Debit") -> 147
A7: Средний доход | B7: =IFERROR(B2/B5, 0) -> 798.36575
A8: Средний расход | B8: =IFERROR(B3/B6, 0) -> 293.87075
A9: Структура расходов
A10: Категория | B10: Сумма | C10: % от расходов
A11: COGS | B11: =SUMIFS('Основной счет'!F:F, 'Основной счет'!D:D, "COGS", 'Основной счет'!E:E, "Debit") -> 16991 | C11: =IFERROR(B11/$B$15, 0) -> 0.39331929
A12: Аренда | B12: =SUMIFS('Основной счет'!F:F, 'Основной счет'!C:C, "Rent Payment", 'Основной счет'!E:E, "Debit") -> 8061 | C12: =IFERROR(B12/$B$15, 0) -> 0.18660154
A13: Коммунальные | B13: =SUMIFS('Основной счет'!F:F, 'Основной счет'!C:C, "Utility Bill Payment", 'Основной счет'!E:E, "Debit") -> 9552 | C13: =IFERROR(B13/$B$15, 0) -> 0.22111623
A14: Обслуживание | B14: =SUMIFS('Основной счет'!F:F, 'Основной счет'!C:C, "Maintenance Payment", 'Основной счет'!E:E, "Debit") -> 8595 | C14: =IFERROR(B14/$B$15, 0) -> 0.19896294
A15: Итого расходов: | B15: =SUM(B11:B14) -> 43199 | C15: =SUM(C11:C14) -> 1
A16: Ежемесячная динамика
A17: Год | B17: Месяц | C17: № месяца | D17: Доходы | E17: Расходы | F17: Прибыль | G17: Маржинальность %
A18: 2022 | B18: Январь | C18: 1 | D18: =SUMIFS('Основной счет'!F:F, 'Основной счет'!H:H, A18, 'Основной счет'!I:I, C18, 'Основной счет'!E:E, "Credit") -> 29463 | E18: =SUMIFS('Основной счет'!F:F, 'Основной счет'!H:H, A18, 'Основной счет'!I:I, C18, 'Основной счет'!E:E, "Debit") -> 3485 | F18: =D18-E18 -> 25978 | G18: =IFERROR(F18/D18, 0) -> 0.88171605
A19: 2022 | B19: Февраль | C19: =C18+1 -> 2 | D19: =SUMIFS('Основной счет'!F:F, 'Основной счет'!H:H, A19, 'Основной счет'!I:I, C19, 'Основной счет'!E:E, "Credit") -> 26196 | E19: =SUMIFS('Основной счет'!F:F, 'Основной счет'!H:H, A19, 'Основной счет'!I:I, C19, 'Основной счет'!E:E, "Debit") -> 1634 | F19: =D19-E19 -> 24562 | G19: =IFERROR(F19/D19, 0) -> 0.93762406
A20: 2022 | B20: Март | C20: =C19+1 -> 3 | D20: =SUMIFS('Основной счет'!F:F, 'Основной счет'!H:H, A20, 'Основной счет'!I:I, C20, 'Основной счет'!E:E, "Credit") -> 18894 | E20: =SUMIFS('Основной счет'!F:F, 'Основной счет'!H:H, A20, 'Основной счет'!I:I, C20, 'Основной счет'!E:E, "Debit") -> 1635 | F20: =D20-E20 -> 17259 | G20: =IFERROR(F20/D20, 0) -> 0.91346459
A21: 2022 | B21: Апрель | C21: =C20+1 -> 4 | D21: =SUMIFS('Основной счет'!F:F, 'Основной счет'!H:H, A21, 'Основной счет'!I:I, C21, 'Основной счет'!E:E, "Credit") -> 18012 | E21: =SUMIFS('Основной счет'!F:F, 'Основной счет'!H:H, A21, 'Основной счет'!I:I, C21, 'Основной счет'!E:E, "Debit") -> 1284 | F21: =D21-E21 -> 16728 | G21: =IFERROR(F21/D21, 0) -> 0.92871419
A22: 2022 | B22: Май | C22: =C21+1 -> 5 | D22: =SUMIFS('Основной счет'!F:F, 'Основной счет'!H:H, A22, 'Основной счет'!I:I, C22, 'Основной счет'!E:E, "Credit") -> 18550 | E22: =SUMIFS('Основной счет'!F:F, 'Основной счет'!H:H, A22, 'Основной счет'!I:I, C22, 'Основной счет'!E:E, "Debit") -> 1137 | F22: =D22-E22 -> 17413 | G22: =IFERROR(F22/D22, 0) -> 0.9387062
A23: 2022 | B23: Июнь | C23: =C22+1 -> 6 | D23: =SUMIFS('Основной счет'!F:F, 'Основной счет'!H:H, A23, 'Основной счет'!I:I, C23, 'Основной счет'!E:E, "Credit") -> 17820 | E23: =SUMIFS('Основной счет'!F:F, 'Основной счет'!H:H, A23, 'Основной счет'!I:I, C23, 'Основной счет'!E:E, "Debit") -> 2823 | F23: =D23-E23 -> 14997 | G23: =IFERROR(F23/D23, 0) -> 0.84158249
A24: 2022 | B24: Июль | C24: =C23+1 -> 7 | D24: =SUMIFS('Основной счет'!F:F, 'Основной счет'!H:H, A24, 'Основной счет'!I:I, C24, 'Основной счет'!E:E, "Credit") -> 23232 | E24: =SUMIFS('Основной счет'!F:F, 'Основной счет'!H:H, A24, 'Основной счет'!I:I, C24, 'Основной счет'!E:E, "Debit") -> 1779 | F24: =D24-E24 -> 21453 | G24: =IFERROR(F24/D24, 0) -> 0.92342459
A25: 2022 | B25: Август | C25: =C24+1 -> 8 | D25: =SUMIFS('Основной счет'!F:F, 'Основной счет'!H:H, A25, 'Основной счет'!I:I, C25, 'Основной счет'!E:E, "Credit") -> 22841 | E25: =SUMIFS('Основной счет'!F:F, 'Основной счет'!H:H, A25, 'Основной счет'!I:I, C25, 'Основной счет'!E:E, "Debit") -> 2535 | F25: =D25-E25 -> 20306 | G25: =IFERROR(F25/D25, 0) -> 0.88901537
A26: 2022 | B26: Сентябрь | C26: =C25+1 -> 9 | D26: =SUMIFS('Основной счет'!F:F, 'Основной счет'!H:H, A26, 'Основной счет'!I:I, C26, 'Основной счет'!E:E, "Credit") -> 29391 | E26: =SUMIFS('Основной счет'!F:F, 'Основной счет'!H:H, A26, 'Основной счет'!I:I, C26, 'Основной счет'!E:E, "Debit") -> 1259 | F26: =D26-E26 -> 28132 | G26: =IFERROR(F26/D26, 0) -> 0.95716376
A27: 2022 | B27: Октябрь | C27: =C26+1 -> 10 | D27: =SUMIFS('Основной счет'!F:F, 'Основной счет'!H:H, A27, 'Основной счет'!I:I, C27, 'Основной счет'!E:E, "Credit") -> 30424 | E27: =SUMIFS('Основной счет'!F:F, 'Основной счет'!H:H, A27, 'Основной счет'!I:I, C27, 'Основной счет'!E:E, "Debit") -> 1234 | F27: =D27-E27 -> 29190 | G27: =IFERROR(F27/D27, 0) -> 0.95943992
A28: 2022 | B28: Ноябрь | C28: =C27+1 -> 11 | D28: =SUMIFS('Основной счет'!F:F, 'Основной счет'!H:H, A28, 'Основной счет'!I:I, C28, 'Основной счет'!E:E, "Credit") -> 28391 | E28: =SUMIFS('Основной счет'!F:F, 'Основной счет'!H:H, A28, 'Основной счет'!I:I, C28, 'Основной счет'!E:E, "Debit") -> 2369 | F28: =D28-E28 -> 26022 | G28: =IFERROR(F28/D28, 0) -> 0.91655806
A29: 2022 | B29: Декабрь | C29: =C28+1 -> 12 | D29: =SUMIFS('Основной счет'!F:F, 'Основной счет'!H:H, A29, 'Основной счет'!I:I, C29, 'Основной счет'!E:E, "Credit") -> 28351 | E29: =SUMIFS('Основной счет'!F:F, 'Основной счет'!H:H, A29, 'Основной счет'!I:I, C29, 'Основной счет'!E:E, "Debit") -> 1868 | F29: =D29-E29 -> 26483 | G29: =IFERROR(F29/D29, 0) -> 0.93411167
A31: 2023 | B31: Январь | C31: 1 | D31: =SUMIFS('Основной счет'!F:F, 'Основной счет'!H:H, A31, 'Основной счет'!I:I, C31, 'Основной счет'!E:E, "Credit") -> 30248 | E31: =SUMIFS('Основной счет'!F:F, 'Основной счет'!H:H, A31, 'Основной счет'!I:I, C31, 'Основной счет'!E:E, "Debit") -> 2525 | F31: =D31-E31 -> 27723 | G31: =IFERROR(F31/D31, 0) -> 0.91652341
A32: 2023 | B32: Февраль | C32: =C31+1 -> 2 | D32: =SUMIFS('Основной счет'!F:F, 'Основной счет'!H:H, A32, 'Основной счет'!I:I, C32, 'Основной счет'!E:E, "Credit") -> 25404 | E32: =SUMIFS('Основной счет'!F:F, 'Основной счет'!H:H, A32, 'Основной счет'!I:I, C32, 'Основной счет'!E:E, "Debit") -> 942 | F32: =D32-E32 -> 24462 | G32: =IFERROR(F32/D32, 0) -> 0.96291923
A33: 2023 | B33: Март | C33: =C32+1 -> 3 | D33: =SUMIFS('Основной счет'!F:F, 'Основной счет'!H:H, A33, 'Основной счет'!I:I, C33, 'Основной счет'!E:E, "Credit") -> 19541 | E33: =SUMIFS('Основной счет'!F:F, 'Основной счет'!H:H, A33, 'Основной счет'!I:I, C33, 'Основной счет'!E:E, "Debit") -> 1510 | F33: =D33-E33 -> 18031 | G33: =IFERROR(F33/D33, 0) -> 0.92272657
A34: 2023 | B34: Апрель | C34: =C33+1 -> 4 | D34: =SUMIFS('Основной счет'!F:F, 'Основной счет'!H:H, A34, 'Основной счет'!I:I, C34, 'Основной счет'!E:E, "Credit") -> 18920 | E34: =SUMIFS('Основной счет'!F:F, 'Основной счет'!H:H, A34, 'Основной счет'!I:I, C34, 'Основной счет'!E:E, "Debit") -> 1464 | F34: =D34-E34 -> 17456 | G34: =IFERROR(F34/D34, 0) -> 0.92262156
A35: 2023 | B35: Май | C35: =C34+1 -> 5 | D35: =SUMIFS('Основной счет'!F:F, 'Основной счет'!H:H, A35, 'Основной счет'!I:I, C35, 'Основной счет'!E:E, "Credit") -> 18462 | E35: =SUMIFS('Основной счет'!F:F, 'Основной счет'!H:H, A35, 'Основной счет'!I:I, C35, 'Основной счет'!E:E, "Debit") -> 844 | F35: =D35-E35 -> 17618 | G35: =IFERROR(F35/D35, 0) -> 0.95428448
A36: 2023 | B36: Июнь | C36: =C35+1 -> 6 | D36: =SUMIFS('Основной счет'!F:F, 'Основной счет'!H:H, A36, 'Основной счет'!I:I, C36, 'Основной счет'!E:E, "Credit") -> 17932 | E36: =SUMIFS('Основной счет'!F:F, 'Основной счет'!H:H, A36, 'Основной счет'!I:I, C36, 'Основной счет'!E:E, "Debit") -> 1890 | F36: =D36-E36 -> 16042 | G36: =IFERROR(F36/D36, 0) -> 0.89460183
A37: 2023 | B37: Июль | C37: =C36+1 -> 7 | D37: =SUMIFS('Основной счет'!F:F, 'Основной счет'!H:H, A37, 'Основной счет'!I:I, C37, 'Основной счет'!E:E, "Credit") -> 23166 | E37: =SUMIFS('Основной счет'!F:F, 'Основной счет'!H:H, A37, 'Основной счет'!I:I, C37, 'Основной счет'!E:E, "Debit") -> 1691 | F37: =D37-E37 -> 21475 | G37: =IFERROR(F37/D37, 0) -> 0.92700509
A38: 2023 | B38: Август | C38: =C37+1 -> 8 | D38: =SUMIFS('Основной счет'!F:F, 'Основной счет'!H:H, A38, 'Основной счет'!I:I, C38, 'Основной счет'!E:E, "Credit") -> 23650 | E38: =SUMIFS('Основной счет'!F:F, 'Основной счет'!H:H, A38, 'Основной счет'!I:I, C38, 'Основной счет'!E:E, "Debit") -> 1273 | F38: =D38-E38 -> 22377 | G38: =IFERROR(F38/D38, 0) -> 0.94617336
A39: 2023 | B39: Сентябрь | C39: =C38+1 -> 9 | D39: =SUMIFS('Основной счет'!F:F, 'Основной счет'!H:H, A39, 'Основной счет'!I:I, C39, 'Основной счет'!E:E, "Credit") -> 26576 | E39: =SUMIFS('Основной счет'!F:F, 'Основной счет'!H:H, A39, 'Основной счет'!I:I, C39, 'Основной счет'!E:E, "Debit") -> 1838 | F39: =D39-E39 -> 24738 | G39: =IFERROR(F39/D39, 0) -> 0.93083986
A40: 2023 | B40: Октябрь | C40: =C39+1 -> 10 | D40: =SUMIFS('Основной счет'!F:F, 'Основной счет'!H:H, A40, 'Основной счет'!I:I, C40, 'Основной счет'!E:E, "Credit") -> 29226 | E40: =SUMIFS('Основной счет'!F:F, 'Основной счет'!H:H, A40, 'Основной счет'!I:I, C40, 'Основной счет'!E:E, "Debit") -> 1585 | F40: =D40-E40 -> 27641 | G40: =IFERROR(F40/D40, 0) -> 0.94576747
A41: 2023 | B41: Ноябрь | C41: =C40+1 -> 11 | D41: =SUMIFS('Основной счет'!F:F, 'Основной счет'!H:H, A41, 'Основной счет'!I:I, C41, 'Основной счет'!E:E, "Credit") -> 29072 | E41: =SUMIFS('Основной счет'!F:F, 'Основной счет'!H:H, A41, 'Основной счет'!I:I, C41, 'Основной счет'!E:E, "Debit") -> 2212 | F41: =D41-E41 -> 26860 | G41: =IFERROR(F41/D41, 0) -> 0.92391304
...

Sheet Расчеты_второй
A1: Общая статистика
A2: Поступления | B2: =SUMIF('Второй счет'!E:E, "Credit", 'Второй счет'!F:F) -> 110617
A3: Списания | B3: =SUMIF('Второй счет'!E:E, "Debit", 'Второй счет'!F:F) -> 97811
A4: Остаток на счете | B4: =B2-B3 -> 12806
A5: Кол-во поступллений | B5: =COUNTIF('Второй счет'!E:E, "Credit") -> 24
A6: Кол-во списаний | B6: =COUNTIF('Второй счет'!E:E, "Debit") -> 24
A7: Среднее поступление | B7: =IFERROR(B2/B5, 0) -> 4609.0417
A8: Среднее списание | B8: =IFERROR(B3/B6, 0) -> 4075.4583
A9: Ежемесячная динамика
A10: Год | B10: Месяц | C10: № месяца | D10: Поступления | E10: Списания | F10: Чистый поток | G10: Эффективность %
A11: 2022 | B11: Январь | C11: 1 | D11: =SUMIFS('Второй счет'!F:F, 'Второй счет'!H:H, A11, 'Второй счет'!I:I, C11, 'Второй счет'!E:E, "Credit") -> 3403 | E11: =SUMIFS('Второй счет'!F:F, 'Второй счет'!H:H, A11, 'Второй счет'!I:I, C11, 'Второй счет'!E:E, "Debit") -> 2688 | F11: =D11-E11 -> 715 | G11: =IFERROR(E11/D11, 0) -> 0.78989127
A12: 2022 | B12: Февраль | C12: =C11+1 -> 2 | D12: =SUMIFS('Второй счет'!F:F, 'Второй счет'!H:H, A12, 'Второй счет'!I:I, C12, 'Второй счет'!E:E, "Credit") -> 5779 | E12: =SUMIFS('Второй счет'!F:F, 'Второй счет'!H:H, A12, 'Второй счет'!I:I, C12, 'Второй счет'!E:E, "Debit") -> 5216 | F12: =D12-E12 -> 563 | G12: =IFERROR(E12/D12, 0) -> 0.9025783
A13: 2022 | B13: Март | C13: =C12+1 -> 3 | D13: =SUMIFS('Второй счет'!F:F, 'Второй счет'!H:H, A13, 'Второй счет'!I:I, C13, 'Второй счет'!E:E, "Credit") -> 5579 | E13: =SUMIFS('Второй счет'!F:F, 'Второй счет'!H:H, A13, 'Второй счет'!I:I, C13, 'Второй счет'!E:E, "Debit") -> 5228 | F13: =D13-E13 -> 351 | G13: =IFERROR(E13/D13, 0) -> 0.9370855
A14: 2022 | B14: Апрель | C14: =C13+1 -> 4 | D14: =SUMIFS('Второй счет'!F:F, 'Второй счет'!H:H, A14, 'Второй счет'!I:I, C14, 'Второй счет'!E:E, "Credit") -> 4712 | E14: =SUMIFS('Второй счет'!F:F, 'Второй счет'!H:H, A14, 'Второй счет'!I:I, C14, 'Второй счет'!E:E, "Debit") -> 4093 | F14: =D14-E14 -> 619 | G14: =IFERROR(E14/D14, 0) -> 0.86863328
A15: 2022 | B15: Май | C15: =C14+1 -> 5 | D15: =SUMIFS('Второй счет'!F:F, 'Второй счет'!H:H, A15, 'Второй счет'!I:I, C15, 'Второй счет'!E:E, "Credit") -> 4273 | E15: =SUMIFS('Второй счет'!F:F, 'Второй счет'!H:H, A15, 'Второй счет'!I:I, C15, 'Второй счет'!E:E, "Debit") -> 3957 | F15: =D15-E15 -> 316 | G15: =IFERROR(E15/D15, 0) -> 0.92604727
A16: 2022 | B16: Июнь | C16: =C15+1 -> 6 | D16: =SUMIFS('Второй счет'!F:F, 'Второй счет'!H:H, A16, 'Второй счет'!I:I, C16, 'Второй счет'!E:E, "Credit") -> 5913 | E16: =SUMIFS('Второй счет'!F:F, 'Второй счет'!H:H, A16, 'Второй счет'!I:I, C16, 'Второй счет'!E:E, "Debit") -> 5202 | F16: =D16-E16 -> 711 | G16: =IFERROR(E16/D16, 0) -> 0.87975647
A17: 2022 | B17: Июль | C17: =C16+1 -> 7 | D17: =SUMIFS('Второй счет'!F:F, 'Второй счет'!H:H, A17, 'Второй счет'!I:I, C17, 'Второй счет'!E:E, "Credit") -> 5625 | E17: =SUMIFS('Второй счет'!F:F, 'Второй счет'!H:H, A17, 'Второй счет'!I:I, C17, 'Второй счет'!E:E, "Debit") -> 5091 | F17: =D17-E17 -> 534 | G17: =IFERROR(E17/D17, 0) -> 0.90506667
A18: 2022 | B18: Август | C18: =C17+1 -> 8 | D18: =SUMIFS('Второй счет'!F:F, 'Второй счет'!H:H, A18, 'Второй счет'!I:I, C18, 'Второй счет'!E:E, "Credit") -> 4441 | E18: =SUMIFS('Второй счет'!F:F, 'Второй счет'!H:H, A18, 'Второй счет'!I:I, C18, 'Второй счет'!E:E, "Debit") -> 3947 | F18: =D18-E18 -> 494 | G18: =IFERROR(E18/D18, 0) -> 0.88876379
A19: 2022 | B19: Сентябрь | C19: =C18+1 -> 9 | D19: =SUMIFS('Второй счет'!F:F, 'Второй счет'!H:H, A19, 'Второй счет'!I:I, C19, 'Второй счет'!E:E, "Credit") -> 3754 | E19: =SUMIFS('Второй счет'!F:F, 'Второй счет'!H:H, A19, 'Второй счет'!I:I, C19, 'Второй счет'!E:E, "Debit") -> 3184 | F19: =D19-E19 -> 570 | G19: =IFERROR(E19/D19, 0) -> 0.84816196
A20: 2022 | B20: Октябрь | C20: =C19+1 -> 10 | D20: =SUMIFS('Второй счет'!F:F, 'Второй счет'!H:H, A20, 'Второй счет'!I:I, C20, 'Второй счет'!E:E, "Credit") -> 3185 | E20: =SUMIFS('Второй счет'!F:F, 'Второй счет'!H:H, A20, 'Второй счет'!I:I, C20, 'Второй счет'!E:E, "Debit") -> 2740 | F20: =D20-E20 -> 445 | G20: =IFERROR(E20/D20, 0) -> 0.86028257
A21: 2022 | B21: Ноябрь | C21: =C20+1 -> 11 | D21: =SUMIFS('Второй счет'!F:F, 'Второй счет'!H:H, A21, 'Второй счет'!I:I, C21, 'Второй счет'!E:E, "Credit") -> 3636 | E21: =SUMIFS('Второй счет'!F:F, 'Второй счет'!H:H, A21, 'Второй счет'!I:I, C21, 'Второй счет'!E:E, "Debit") -> 3169 | F21: =D21-E21 -> 467 | G21: =IFERROR(E21/D21, 0) -> 0.87156216
A22: 2022 | B22: Декабрь | C22: =C21+1 -> 12 | D22: =SUMIFS('Второй счет'!F:F, 'Второй счет'!H:H, A22, 'Второй счет'!I:I, C22, 'Второй счет'!E:E, "Credit") -> 3529 | E22: =SUMIFS('Второй счет'!F:F, 'Второй счет'!H:H, A22, 'Второй счет'!I:I, C22, 'Второй счет'!E:E, "Debit") -> 2778 | F22: =D22-E22 -> 751 | G22: =IFERROR(E22/D22, 0) -> 0.78719184
A24: 2023 | B24: Январь | C24: 1 | D24: =SUMIFS('Второй счет'!F:F, 'Второй счет'!H:H, A24, 'Второй счет'!I:I, C24, 'Второй счет'!E:E, "Credit") -> 5068 | E24: =SUMIFS('Второй счет'!F:F, 'Второй счет'!H:H, A24, 'Второй счет'!I:I, C24, 'Второй счет'!E:E, "Debit") -> 4349 | F24: =D24-E24 -> 719 | G24: =IFERROR(E24/D24, 0) -> 0.85812944
A25: 2023 | B25: Февраль | C25: =C24+1 -> 2 | D25: =SUMIFS('Второй счет'!F:F, 'Второй счет'!H:H, A25, 'Второй счет'!I:I, C25, 'Второй счет'!E:E, "Credit") -> 5147 | E25: =SUMIFS('Второй счет'!F:F, 'Второй счет'!H:H, A25, 'Второй счет'!I:I, C25, 'Второй счет'!E:E, "Debit") -> 4470 | F25: =D25-E25 -> 677 | G25: =IFERROR(E25/D25, 0) -> 0.86846707
A26: 2023 | B26: Март | C26: =C25+1 -> 3 | D26: =SUMIFS('Второй счет'!F:F, 'Второй счет'!H:H, A26, 'Второй счет'!I:I, C26, 'Второй счет'!E:E, "Credit") -> 4622 | E26: =SUMIFS('Второй счет'!F:F, 'Второй счет'!H:H, A26, 'Второй счет'!I:I, C26, 'Второй счет'!E:E, "Debit") -> 4125 | F26: =D26-E26 -> 497 | G26: =IFERROR(E26/D26, 0) -> 0.89247079
A27: 2023 | B27: Апрель | C27: =C26+1 -> 4 | D27: =SUMIFS('Второй счет'!F:F, 'Второй счет'!H:H, A27, 'Второй счет'!I:I, C27, 'Второй счет'!E:E, "Credit") -> 3939 | E27: =SUMIFS('Второй счет'!F:F, 'Второй счет'!H:H, A27, 'Второй счет'!I:I, C27, 'Второй счет'!E:E, "Debit") -> 3214 | F27: =D27-E27 -> 725 | G27: =IFERROR(E27/D27, 0) -> 0.81594313
A28: 2023 | B28: Май | C28: =C27+1 -> 5 | D28: =SUMIFS('Второй счет'!F:F, 'Второй счет'!H:H, A28, 'Второй счет'!I:I, C28, 'Второй счет'!E:E, "Credit") -> 5381 | E28: =SUMIFS('Второй счет'!F:F, 'Второй счет'!H:H, A28, 'Второй счет'!I:I, C28, 'Второй счет'!E:E, "Debit") -> 5180 | F28: =D28-E28 -> 201 | G28: =IFERROR(E28/D28, 0) -> 0.96264635
A29: 2023 | B29: Июнь | C29: =C28+1 -> 6 | D29: =SUMIFS('Второй счет'!F:F, 'Второй счет'!H:H, A29, 'Второй счет'!I:I, C29, 'Второй счет'!E:E, "Credit") -> 3374 | E29: =SUMIFS('Второй счет'!F:F, 'Второй счет'!H:H, A29, 'Второй счет'!I:I, C29, 'Второй счет'!E:E, "Debit") -> 2882 | F29: =D29-E29 -> 492 | G29: =IFERROR(E29/D29, 0) -> 0.85417902
A30: 2023 | B30: Июль | C30: =C29+1 -> 7 | D30: =SUMIFS('Второй счет'!F:F, 'Второй счет'!H:H, A30, 'Второй счет'!I:I, C30, 'Второй счет'!E:E, "Credit") -> 5884 | E30: =SUMIFS('Второй счет'!F:F, 'Второй счет'!H:H, A30, 'Второй счет'!I:I, C30, 'Второй счет'!E:E, "Debit") -> 5132 | F30: =D30-E30 -> 752 | G30: =IFERROR(E30/D30, 0) -> 0.87219579
A31: 2023 | B31: Август | C31: =C30+1 -> 8 | D31: =SUMIFS('Второй счет'!F:F, 'Второй счет'!H:H, A31, 'Второй счет'!I:I, C31, 'Второй счет'!E:E, "Credit") -> 5365 | E31: =SUMIFS('Второй счет'!F:F, 'Второй счет'!H:H, A31, 'Второй счет'!I:I, C31, 'Второй счет'!E:E, "Debit") -> 4664 | F31: =D31-E31 -> 701 | G31: =IFERROR(E31/D31, 0) -> 0.8693383
A32: 2023 | B32: Сентябрь | C32: =C31+1 -> 9 | D32: =SUMIFS('Второй счет'!F:F, 'Второй счет'!H:H, A32, 'Второй счет'!I:I, C32, 'Второй счет'!E:E, "Credit") -> 4851 | E32: =SUMIFS('Второй счет'!F:F, 'Второй счет'!H:H, A32, 'Второй счет'!I:I, C32, 'Второй счет'!E:E, "Debit") -> 4271 | F32: =D32-E32 -> 580 | G32: =IFERROR(E32/D32, 0) -> 0.88043702
A33: 2023 | B33: Октябрь | C33: =C32+1 -> 10 | D33: =SUMIFS('Второй счет'!F:F, 'Второй счет'!H:H, A33, 'Второй счет'!I:I, C33, 'Второй счет'!E:E, "Credit") -> 4646 | E33: =SUMIFS('Второй счет'!F:F, 'Второй счет'!H:H, A33, 'Второй счет'!I:I, C33, 'Второй счет'!E:E, "Debit") -> 4433 | F33: =D33-E33 -> 213 | G33: =IFERROR(E33/D33, 0) -> 0.95415411
A34: 2023 | B34: Ноябрь | C34: =C33+1 -> 11 | D34: =SUMIFS('Второй счет'!F:F, 'Второй счет'!H:H, A34, 'Второй счет'!I:I, C34, 'Второй счет'!E:E, "Credit") -> 3503 | E34: =SUMIFS('Второй счет'!F:F, 'Второй счет'!H:H, A34, 'Второй счет'!I:I, C34, 'Второй счет'!E:E, "Debit") -> 3073 | F34: =D34-E34 -> 430 | G34: =IFERROR(E34/D34, 0) -> 0.87724807
A35: 2023 | B35: Декабрь | C35: =C34+1 -> 12 | D35: =SUMIFS('Второй счет'!F:F, 'Второй счет'!H:H, A35, 'Второй счет'!I:I, C35, 'Второй счет'!E:E, "Credit") -> 5008 | E35: =SUMIFS('Второй счет'!F:F, 'Второй счет'!H:H, A35, 'Второй счет'!I:I, C35, 'Второй счет'!E:E, "Debit") -> 4725 | F35: =D35-E35 -> 283 | G35: =IFERROR(E35/D35, 0) -> 0.94349042
A36: Итоги по годам
A37: Показатель | B37: 2022 | C37: 2023 | D37: Изменение %
A38: Всего поступлений | B38: =SUMIFS('Второй счет'!F:F, 'Второй счет'!H:H, 2022, 'Второй счет'!E:E, "Credit") -> 53829 | C38: =SUMIFS('Второй счет'!F:F, 'Второй счет'!H:H, 2023, 'Второй счет'!E:E, "Credit") -> 56788 | D38: =IFERROR((C38-B38)/B38, 0) -> 0.054970369
A39: Всего списаний | B39: =SUMIFS('Второй счет'!F:F, 'Второй счет'!H:H, 2022, 'Второй счет'!E:E, "Debit") -> 47293 | C39: =SUMIFS('Второй счет'!F:F, 'Второй счет'!H:H, 2023, 'Второй счет'!E:E, "Debit") -> 50518 | D39: =IFERROR((C39-B39)/B39, 0) -> 0.06819191
A40: Чистый поток | B40: =B38-B39 -> 6536 | C40: =C38-C39 -> 6270 | D40: =IFERROR((C40-B40)/B40, 0) -> -0.040697674

Sheet Рассчеты_зп
A1: Общая статистика
A2: Всего зарплат | B2: =SUM(Зарплаты!F:F) -> 159854
A3: Всего сотрудникам | B3: =SUMIF(Зарплаты!N:N,TRUE,Зарплаты!F:F) -> 132001
A4: Всего контракторам | B4: =SUMIF(Зарплаты!O:O,TRUE,Зарплаты!F:F) -> 27853
A5: Кол-во записей | B5: =COUNTA(Зарплаты!F:F)-1 -> 92
A6: Кол-во сотрудников | B6: =COUNTIF(Зарплаты!N:N,TRUE) -> 69
A7: Кол-во контракторов | B7: =COUNTIF(Зарплаты!O:O,TRUE) -> 23
A8: Средняя зарплата | B8: =B2/B5 -> 1737.5435
A9: Средняя зп сотрудника | B9: =B3/B6 -> 1913.058
A10: Средняя зп контрактора | B10: =B4/B7 -> 1211
A11: Ежемесячная динамика зарплат
A12: Год | B12: Месяц | C12: № месяца | D12: Сотрудники | E12: Контракторы | F12: Итого | G12: % контракторов
A13: 2022 | B13: Январь | C13: 1 | D13: =SUMIFS(Зарплаты!F:F, Зарплаты!H:H, A13, Зарплаты!I:I, C13, Зарплаты!N:N, TRUE) -> 0 | E13: =SUMIFS(Зарплаты!F:F, Зарплаты!H:H, A13, Зарплаты!I:I, C13, Зарплаты!O:O, TRUE) -> 0 | F13: =D13+E13 -> 0 | G13: =IFERROR(E13/F13, 0) -> 0
A14: 2022 | B14: Февраль | C14: =C13+1 -> 2 | D14: =SUMIFS(Зарплаты!F:F, Зарплаты!H:H, A14, Зарплаты!I:I, C14, Зарплаты!N:N, TRUE) -> 5868 | E14: =SUMIFS(Зарплаты!F:F, Зарплаты!H:H, A14, Зарплаты!I:I, C14, Зарплаты!O:O, TRUE) -> 1134 | F14: =D14+E14 -> 7002 | G14: =IFERROR(E14/F14, 0) -> 0.16195373
A15: 2022 | B15: Март | C15: =C14+1 -> 3 | D15: =SUMIFS(Зарплаты!F:F, Зарплаты!H:H, A15, Зарплаты!I:I, C15, Зарплаты!N:N, TRUE) -> 5897 | E15: =SUMIFS(Зарплаты!F:F, Зарплаты!H:H, A15, Зарплаты!I:I, C15, Зарплаты!O:O, TRUE) -> 1166 | F15: =D15+E15 -> 7063 | G15: =IFERROR(E15/F15, 0) -> 0.16508566
A16: 2022 | B16: Апрель | C16: =C15+1 -> 4 | D16: =SUMIFS(Зарплаты!F:F, Зарплаты!H:H, A16, Зарплаты!I:I, C16, Зарплаты!N:N, TRUE) -> 5714 | E16: =SUMIFS(Зарплаты!F:F, Зарплаты!H:H, A16, Зарплаты!I:I, C16, Зарплаты!O:O, TRUE) -> 1113 | F16: =D16+E16 -> 6827 | G16: =IFERROR(E16/F16, 0) -> 0.16302915
A17: 2022 | B17: Май | C17: =C16+1 -> 5 | D17: =SUMIFS(Зарплаты!F:F, Зарплаты!H:H, A17, Зарплаты!I:I, C17, Зарплаты!N:N, TRUE) -> 5812 | E17: =SUMIFS(Зарплаты!F:F, Зарплаты!H:H, A17, Зарплаты!I:I, C17, Зарплаты!O:O, TRUE) -> 1262 | F17: =D17+E17 -> 7074 | G17: =IFERROR(E17/F17, 0) -> 0.17839977
A18: 2022 | B18: Июнь | C18: =C17+1 -> 6 | D18: =SUMIFS(Зарплаты!F:F, Зарплаты!H:H, A18, Зарплаты!I:I, C18, Зарплаты!N:N, TRUE) -> 5734 | E18: =SUMIFS(Зарплаты!F:F, Зарплаты!H:H, A18, Зарплаты!I:I, C18, Зарплаты!O:O, TRUE) -> 1262 | F18: =D18+E18 -> 6996 | G18: =IFERROR(E18/F18, 0) -> 0.18038879
A19: 2022 | B19: Июль | C19: =C18+1 -> 7 | D19: =SUMIFS(Зарплаты!F:F, Зарплаты!H:H, A19, Зарплаты!I:I, C19, Зарплаты!N:N, TRUE) -> 5502 | E19: =SUMIFS(Зарплаты!F:F, Зарплаты!H:H, A19, Зарплаты!I:I, C19, Зарплаты!O:O, TRUE) -> 1293 | F19: =D19+E19 -> 6795 | G19: =IFERROR(E19/F19, 0) -> 0.19028698
A20: 2022 | B20: Август | C20: =C19+1 -> 8 | D20: =SUMIFS(Зарплаты!F:F, Зарплаты!H:H, A20, Зарплаты!I:I, C20, Зарплаты!N:N, TRUE) -> 5559 | E20: =SUMIFS(Зарплаты!F:F, Зарплаты!H:H, A20, Зарплаты!I:I, C20, Зарплаты!O:O, TRUE) -> 1263 | F20: =D20+E20 -> 6822 | G20: =IFERROR(E20/F20, 0) -> 0.18513632
A21: 2022 | B21: Сентябрь | C21: =C20+1 -> 9 | D21: =SUMIFS(Зарплаты!F:F, Зарплаты!H:H, A21, Зарплаты!I:I, C21, Зарплаты!N:N, TRUE) -> 5621 | E21: =SUMIFS(Зарплаты!F:F, Зарплаты!H:H, A21, Зарплаты!I:I, C21, Зарплаты!O:O, TRUE) -> 1209 | F21: =D21+E21 -> 6830 | G21: =IFERROR(E21/F21, 0) -> 0.17701318
A22: 2022 | B22: Октябрь | C22: =C21+1 -> 10 | D22: =SUMIFS(Зарплаты!F:F, Зарплаты!H:H, A22, Зарплаты!I:I, C22, Зарплаты!N:N, TRUE) -> 5706 | E22: =SUMIFS(Зарплаты!F:F, Зарплаты!H:H, A22, Зарплаты!I:I, C22, Зарплаты!O:O, TRUE) -> 1279 | F22: =D22+E22 -> 6985 | G22: =IFERROR(E22/F22, 0) -> 0.18310666
A23: 2022 | B23: Ноябрь | C23: =C22+1 -> 11 | D23: =SUMIFS(Зарплаты!F:F, Зарплаты!H:H, A23, Зарплаты!I:I, C23, Зарплаты!N:N, TRUE) -> 5881 | E23: =SUMIFS(Зарплаты!F:F, Зарплаты!H:H, A23, Зарплаты!I:I, C23, Зарплаты!O:O, TRUE) -> 1124 | F23: =D23+E23 -> 7005 | G23: =IFERROR(E23/F23, 0) -> 0.16045682
A24: 2022 | B24: Декабрь | C24: =C23+1 -> 12 | D24: =SUMIFS(Зарплаты!F:F, Зарплаты!H:H, A24, Зарплаты!I:I, C24, Зарплаты!N:N, TRUE) -> 5841 | E24: =SUMIFS(Зарплаты!F:F, Зарплаты!H:H, A24, Зарплаты!I:I, C24, Зарплаты!O:O, TRUE) -> 1248 | F24: =D24+E24 -> 7089 | G24: =IFERROR(E24/F24, 0) -> 0.1760474
A26: 2023 | B26: Январь | C26: 1 | D26: =SUMIFS(Зарплаты!F:F, Зарплаты!H:H, A26, Зарплаты!I:I, C26, Зарплаты!N:N, TRUE) -> 5747 | E26: =SUMIFS(Зарплаты!F:F, Зарплаты!H:H, A26, Зарплаты!I:I, C26, Зарплаты!O:O, TRUE) -> 1167 | F26: =D26+E26 -> 6914 | G26: =IFERROR(E26/F26, 0) -> 0.16878797
A27: 2023 | B27: Февраль | C27: =C26+1 -> 2 | D27: =SUMIFS(Зарплаты!F:F, Зарплаты!H:H, A27, Зарплаты!I:I, C27, Зарплаты!N:N, TRUE) -> 5820 | E27: =SUMIFS(Зарплаты!F:F, Зарплаты!H:H, A27, Зарплаты!I:I, C27, Зарплаты!O:O, TRUE) -> 1131 | F27: =D27+E27 -> 6951 | G27: =IFERROR(E27/F27, 0) -> 0.1627104
A28: 2023 | B28: Март | C28: =C27+1 -> 3 | D28: =SUMIFS(Зарплаты!F:F, Зарплаты!H:H, A28, Зарплаты!I:I, C28, Зарплаты!N:N, TRUE) -> 5763 | E28: =SUMIFS(Зарплаты!F:F, Зарплаты!H:H, A28, Зарплаты!I:I, C28, Зарплаты!O:O, TRUE) -> 1240 | F28: =D28+E28 -> 7003 | G28: =IFERROR(E28/F28, 0) -> 0.17706697
A29: 2023 | B29: Апрель | C29: =C28+1 -> 4 | D29: =SUMIFS(Зарплаты!F:F, Зарплаты!H:H, A29, Зарплаты!I:I, C29, Зарплаты!N:N, TRUE) -> 5576 | E29: =SUMIFS(Зарплаты!F:F, Зарплаты!H:H, A29, Зарплаты!I:I, C29, Зарплаты!O:O, TRUE) -> 1245 | F29: =D29+E29 -> 6821 | G29: =IFERROR(E29/F29, 0) -> 0.18252456
A30: 2023 | B30: Май | C30: =C29+1 -> 5 | D30: =SUMIFS(Зарплаты!F:F, Зарплаты!H:H, A30, Зарплаты!I:I, C30, Зарплаты!N:N, TRUE) -> 5832 | E30: =SUMIFS(Зарплаты!F:F, Зарплаты!H:H, A30, Зарплаты!I:I, C30, Зарплаты!O:O, TRUE) -> 1259 | F30: =D30+E30 -> 7091 | G30: =IFERROR(E30/F30, 0) -> 0.17754901
A31: 2023 | B31: Июнь | C31: =C30+1 -> 6 | D31: =SUMIFS(Зарплаты!F:F, Зарплаты!H:H, A31, Зарплаты!I:I, C31, Зарплаты!N:N, TRUE) -> 5713 | E31: =SUMIFS(Зарплаты!F:F, Зарплаты!H:H, A31, Зарплаты!I:I, C31, Зарплаты!O:O, TRUE) -> 1159 | F31: =D31+E31 -> 6872 | G31: =IFERROR(E31/F31, 0) -> 0.16865541
A32: 2023 | B32: Июль | C32: =C31+1 -> 7 | D32: =SUMIFS(Зарплаты!F:F, Зарплаты!H:H, A32, Зарплаты!I:I, C32, Зарплаты!N:N, TRUE) -> 5634 | E32: =SUMIFS(Зарплаты!F:F, Зарплаты!H:H, A32, Зарплаты!I:I, C32, Зарплаты!O:O, TRUE) -> 1261 | F32: =D32+E32 -> 6895 | G32: =IFERROR(E32/F32, 0) -> 0.18288615
A33: 2023 | B33: Август | C33: =C32+1 -> 8 | D33: =SUMIFS(Зарплаты!F:F, Зарплаты!H:H, A33, Зарплаты!I:I, C33, Зарплаты!N:N, TRUE) -> 5676 | E33: =SUMIFS(Зарплаты!F:F, Зарплаты!H:H, A33, Зарплаты!I:I, C33, Зарплаты!O:O, TRUE) -> 1225 | F33: =D33+E33 -> 6901 | G33: =IFERROR(E33/F33, 0) -> 0.17751051
A34: 2023 | B34: Сентябрь | C34: =C33+1 -> 9 | D34: =SUMIFS(Зарплаты!F:F, Зарплаты!H:H, A34, Зарплаты!I:I, C34, Зарплаты!N:N, TRUE) -> 5795 | E34: =SUMIFS(Зарплаты!F:F, Зарплаты!H:H, A34, Зарплаты!I:I, C34, Зарплаты!O:O, TRUE) -> 1155 | F34: =D34+E34 -> 6950 | G34: =IFERROR(E34/F34, 0) -> 0.16618705
A35: 2023 | B35: Октябрь | C35: =C34+1 -> 10 | D35: =SUMIFS(Зарплаты!F:F, Зарплаты!H:H, A35, Зарплаты!I:I, C35, Зарплаты!N:N, TRUE) -> 5766 | E35: =SUMIFS(Зарплаты!F:F, Зарплаты!H:H, A35, Зарплаты!I:I, C35, Зарплаты!O:O, TRUE) -> 1248 | F35: =D35+E35 -> 7014 | G35: =IFERROR(E35/F35, 0) -> 0.17792985
A36: 2023 | B36: Ноябрь | C36: =C35+1 -> 11 | D36: =SUMIFS(Зарплаты!F:F, Зарплаты!H:H, A36, Зарплаты!I:I, C36, Зарплаты!N:N, TRUE) -> 5866 | E36: =SUMIFS(Зарплаты!F:F, Зарплаты!H:H, A36, Зарплаты!I:I, C36, Зарплаты!O:O, TRUE) -> 1214 | F36: =D36+E36 -> 7080 | G36: =IFERROR(E36/F36, 0) -> 0.17146893
A37: 2023 | B37: Декабрь | C37: =C36+1 -> 12 | D37: =SUMIFS(Зарплаты!F:F, Зарплаты!H:H, A37, Зарплаты!I:I, C37, Зарплаты!N:N, TRUE) -> 5678 | E37: =SUMIFS(Зарплаты!F:F, Зарплаты!H:H, A37, Зарплаты!I:I, C37, Зарплаты!O:O, TRUE) -> 1196 | F37: =D37+E37 -> 6874 | G37: =IFERROR(E37/F37, 0) -> 0.17398894
A38: Итоги по годам
A39: Показатель | B39: 2022 | C39: 2023 | D39: Изменение %
A40: Всего зарплат | B40: =SUMIF(Зарплаты!H:H, 2022, Зарплаты!F:F) -> 76488 | C40: =SUMIF(Зарплаты!H:H, 2023, Зарплаты!F:F) -> 83366 | D40: =IFERROR((C39-B39)/B39, 0) -> 0.00049455984
A41: Сотрудники | B41: =SUMIFS(Зарплаты!F:F, Зарплаты!H:H, 2022, Зарплаты!N:N, TRUE) -> 63135 | C41: =SUMIFS(Зарплаты!F:F, Зарплаты!H:H, 2023, Зарплаты!N:N, TRUE) -> 68866 | D41: =IFERROR((C41-B41)/B41, 0) -> 0.090773739
...

Sheet Расчеты_кредитка
A1: Всего списаний | B1: =SUMIF('Кредитная карта'!E:E,"Debit",'Кредитная карта'!F:F) -> 36797
A2: Всего платежей | B2: =SUMIF('Кредитная карта'!E:E,"Credit",'Кредитная карта'!F:F) -> 15146
A3: Текущий баланс | B3: =B1-B2 -> 21651
A4: Количество списаний | B4: =COUNTIF('Кредитная карта'!E:E,"Debit") -> 105
A5: Количесвтоп платежей | B5: =COUNTIF('Кредитная карта'!E:E,"Credit") -> 28
A6: Средняя сумма списаний | B6: =B1/B4 -> 350.44762
A7: Средняя сумма платежа | B7: =B2/B5 -> 540.92857
A8: % покрытия долга | B8: =B2/B1*100 -> 41.160964
A9: Траты по критериям
A10: Маркетинг | B10: =SUMIFS('Кредитная карта'!F:F,'Кредитная карта'!D:D,"Marketing",'Кредитная карта'!E:E,"Debit") -> 10030
A11: Коммунальные | B11: =SUMIFS('Кредитная карта'!F:F,'Кредитная карта'!D:D,"Utilities",'Кредитная карта'!E:E,"Debit") -> 9879
A12: Расходные м-лы | B12: =SUMIFS('Кредитная карта'!F:F,'Кредитная карта'!D:D,"Supplies",'Кредитная карта'!E:E,"Debit") -> 6871
A13: Прочее | B13: =SUMIFS('Кредитная карта'!F:F,'Кредитная карта'!D:D,"Other",'Кредитная карта'!E:E,"Debit") -> 10017
A14: Траты по продавцам
A15: Facebook Ads | B15: =SUMIFS('Кредитная карта'!F:F,'Кредитная карта'!C:C,"Facebook Ads",'Кредитная карта'!E:E,"Debit") -> 8459
A16: Utility Company | B16: =SUMIFS('Кредитная карта'!F:F,'Кредитная карта'!C:C,"Utility Company",'Кредитная карта'!E:E,"Debit") -> 9008
A17: Coffee Supplier | B17: =SUMIFS('Кредитная карта'!F:F,'Кредитная карта'!C:C,"Coffee Supplier",'Кредитная карта'!E:E,"Debit") -> 10475
A18: Local Print Shop | B18: =SUMIFS('Кредитная карта'!F:F,'Кредитная карта'!C:C,"Local Print Shop",'Кредитная карта'!E:E,"Debit") -> 8855
A19: Максимальный баланс | B19: =MAX('Кредитная карта'!G:G) -> 21651
A20: Минимальный баланс | B20: =MIN('Кредитная карта'!G:G) -> 229
A21: Месяц с макс тратами | B21: =SUMIFS('Кредитная карта'!F:F, 'Кредитная карта'!H:H, 2022, 'Кредитная карта'!D:D, "Marketing") -> 6176
A22: Общая сумма трат за 2022 | B22: =SUMIFS('Кредитная карта'!F:F,'Кредитная карта'!H:H,2022,'Кредитная карта'!E:E,"Debit") -> 17683
A23: Общая сумма трат за 2023 | B23: =SUMIFS('Кредитная карта'!F:F,'Кредитная карта'!H:H,2023,'Кредитная карта'!E:E,"Debit") -> 19114

Sheet Второй счет
A1: date | B1: transaction_id | C1: description | D1: category | E1: type | F1: amount | G1: balance | H1: year | I1: month | J1: month_name | K1: quarter | L1: day_of_week | M1: day_of_week_num | N1: is_income | O1: is_expense | P1: calculated_balance
A2: 2022-01-01 | B2: SC00001 | C2: Transfer from Main | D2: Transfer | E2: Credit | F2: 3403 | G2: 5403 | H2: 2022 | I2: 1 | J2: January | K2: 1 | L2: Saturday | M2: 5 | N2: TRUE | O2: FALSE | P2: 5403
A3: 2022-01-15 | B3: SC00002 | C3: Payroll Funding | D3: Payroll | E3: Debit | F3: 2688 | G3: 2715 | H3: 2022 | I3: 1 | J3: January | K3: 1 | L3: Saturday | M3: 5 | N3: FALSE | O3: TRUE | P3: 2715
A4: 2022-02-01 | B4: SC00003 | C4: Transfer from Main | D4: Transfer | E4: Credit | F4: 5779 | G4: 8494 | H4: 2022 | I4: 2 | J4: February | K4: 1 | L4: Tuesday | M4: 1 | N4: TRUE | O4: FALSE | P4: 8494
A5: 2022-02-15 | B5: SC00004 | C5: Payroll Funding | D5: Payroll | E5: Debit | F5: 5216 | G5: 3278 | H5: 2022 | I5: 2 | J5: February | K5: 1 | L5: Tuesday | M5: 1 | N5: FALSE | O5: TRUE | P5: 3278
A6: 2022-03-01 | B6: SC00005 | C6: Transfer from Main | D6: Transfer | E6: Credit | F6: 5579 | G6: 8857 | H6: 2022 | I6: 3 | J6: March | K6: 1 | L6: Tuesday | M6: 1 | N6: TRUE | O6: FALSE | P6: 8857
A7: 2022-03-15 | B7: SC00006 | C7: Payroll Funding | D7: Payroll | E7: Debit | F7: 5228 | G7: 3629 | H7: 2022 | I7: 3 | J7: March | K7: 1 | L7: Tuesday | M7: 1 | N7: FALSE | O7: TRUE | P7: 3629
A8: 2022-04-01 | B8: SC00007 | C8: Transfer from Main | D8: Transfer | E8: Credit | F8: 4712 | G8: 8341 | H8: 2022 | I8: 4 | J8: April | K8: 2 | L8: Friday | M8: 4 | N8: TRUE | O8: FALSE | P8: 8341
A9: 2022-04-15 | B9: SC00008 | C9: Payroll Funding | D9: Payroll | E9: Debit | F9: 4093 | G9: 4248 | H9: 2022 | I9: 4 | J9: April | K9: 2 | L9: Friday | M9: 4 | N9: FALSE | O9: TRUE | P9: 4248
A10: 2022-05-01 | B10: SC00009 | C10: Transfer from Main | D10: Transfer | E10: Credit | F10: 4273 | G10: 8521 | H10: 2022 | I10: 5 | J10: May | K10: 2 | L10: Sunday | M10: 6 | N10: TRUE | O10: FALSE | P10: 8521
A11: 2022-05-15 | B11: SC00010 | C11: Payroll Funding | D11: Payroll | E11: Debit | F11: 3957 | G11: 4564 | H11: 2022 | I11: 5 | J11: May | K11: 2 | L11: Sunday | M11: 6 | N11: FALSE | O11: TRUE | P11: 4564
A12: 2022-06-01 | B12: SC00011 | C12: Transfer from Main | D12: Transfer | E12: Credit | F12: 5913 | G12: 10477 | H12: 2022 | I12: 6 | J12: June | K12: 2 | L12: Wednesday | M12: 2 | N12: TRUE | O12: FALSE | P12: 10477
A13: 2022-06-15 | B13: SC00012 | C13: Payroll Funding | D13: Payroll | E13: Debit | F13: 5202 | G13: 5275 | H13: 2022 | I13: 6 | J13: June | K13: 2 | L13: Wednesday | M13: 2 | N13: FALSE | O13: TRUE | P13: 5275
... A49: 2023-12-15 | B49: SC00048 | C49: Payroll Funding | D49: Payroll | E49: Debit | F49: 4725 | G49: 14806 | H49: 2023 | I49: 12 | J49: December | K49: 4 | L49: Friday | M49: 4 | N49: FALSE | O49: TRUE | P49: 14806

Sheet Зарплаты
A1: pay_date | B1: employee_id | C1: employee_name | D1: role | E1: type | F1: amount | G1: account | H1: year | I1: month | J1: month_name | K1: quarter | L1: day_of_week | M1: day_of_week_num | N1: is_employee | O1: is_contractor | P1: role_category
A2: 2022-02-15 | B2: EMP_001 | C2: Employee_001 | D2: Barista | E2: Employee Pay | F2: 1865 | G2: Checking Secondary | H2: 2022 | I2: 2 | J2: February | K2: 1 | L2: Tuesday | M2: 1 | N2: TRUE | O2: FALSE | P2: Barista
A3: 2022-02-15 | B3: EMP_002 | C3: Employee_002 | D3: Barista | E3: Employee Pay | F3: 1731 | G3: Checking Secondary | H3: 2022 | I3: 2 | J3: February | K3: 1 | L3: Tuesday | M3: 1 | N3: TRUE | O3: FALSE | P3: Barista
A4: 2022-02-15 | B4: EMP_003 | C4: Employee_003 | D4: Manager | E4: Employee Pay | F4: 2272 | G4: Checking Secondary | H4: 2022 | I4: 2 | J4: February | K4: 1 | L4: Tuesday | M4: 1 | N4: TRUE | O4: FALSE | P4: Manager
A5: 2022-02-15 | B5: EMP_004 | C5: Employee_004 | D5: Marketing Contractor | E5: Contractor Pay | F5: 1134 | G5: Checking Secondary | H5: 2022 | I5: 2 | J5: February | K5: 1 | L5: Tuesday | M5: 1 | N5: FALSE | O5: TRUE | P5: Contractor
A6: 2022-03-15 | B6: EMP_001 | C6: Employee_001 | D6: Barista | E6: Employee Pay | F6: 1857 | G6: Checking Secondary | H6: 2022 | I6: 3 | J6: March | K6: 1 | L6: Tuesday | M6: 1 | N6: TRUE | O6: FALSE | P6: Barista
A7: 2022-03-15 | B7: EMP_002 | C7: Employee_002 | D7: Barista | E7: Employee Pay | F7: 1807 | G7: Checking Secondary | H7: 2022 | I7: 3 | J7: March | K7: 1 | L7: Tuesday | M7: 1 | N7: TRUE | O7: FALSE | P7: Barista
A8: 2022-03-15 | B8: EMP_003 | C8: Employee_003 | D8: Manager | E8: Employee Pay | F8: 2233 | G8: Checking Secondary | H8: 2022 | I8: 3 | J8: March | K8: 1 | L8: Tuesday | M8: 1 | N8: TRUE | O8: FALSE | P8: Manager
A9: 2022-03-15 | B9: EMP_004 | C9: Employee_004 | D9: Marketing Contractor | E9: Contractor Pay | F9: 1166 | G9: Checking Secondary | H9: 2022 | I9: 3 | J9: March | K9: 1 | L9: Tuesday | M9: 1 | N9: FALSE | O9: TRUE | P9: Contractor
A10: 2022-04-15 | B10: EMP_001 | C10: Employee_001 | D10: Barista | E10: Employee Pay | F10: 1779 | G10: Checking Secondary | H10: 2022 | I10: 4 | J10: April | K10: 2 | L10: Friday | M10: 4 | N10: TRUE | O10: FALSE | P10: Barista
A11: 2022-04-15 | B11: EMP_002 | C11: Employee_002 | D11: Barista | E11: Employee Pay | F11: 1656 | G11: Checking Secondary | H11: 2022 | I11: 4 | J11: April | K11: 2 | L11: Friday | M11: 4 | N11: TRUE | O11: FALSE | P11: Barista
A12: 2022-04-15 | B12: EMP_003 | C12: Employee_003 | D12: Manager | E12: Employee Pay | F12: 2279 | G12: Checking Secondary | H12: 2022 | I12: 4 | J12: April | K12: 2 | L12: Friday | M12: 4 | N12: TRUE | O12: FALSE | P12: Manager
A13: 2022-04-15 | B13: EMP_004 | C13: Employee_004 | D13: Marketing Contractor | E13: Contractor Pay | F13: 1113 | G13: Checking Secondary | H13: 2022 | I13: 4 | J13: April | K13: 2 | L13: Friday | M13: 4 | N13: FALSE | O13: TRUE | P13: Contractor
... A93: 2023-12-15 | B93: EMP_004 | C93: Employee_004 | D93: Marketing Contractor | E93: Contractor Pay | F93: 1196 | G93: Checking Secondary | H93: 2023 | I93: 12 | J93: December | K93: 4 | L93: Friday | M93: 4 | N93: FALSE | O93: TRUE | P93: Contractor

Sheet Кредитная карта
A1: date | B1: transaction_id | C1: vendor | D1: category | E1: type | F1: amount | G1: balance | H1: year | I1: month | J1: month_name | K1: quarter | L1: day_of_week | M1: day_of_week_num | N1: is_purchase | O1: is_payment | P1: calculated_balance
A2: 2022-01-01 | B2: CC00001 | C2: Utility Company | D2: Supplies | E2: Debit | F2: 229 | G2: 229 | H2: 2022 | I2: 1 | J2: January | K2: 1 | L2: Saturday | M2: 5 | N2: TRUE | O2: FALSE | P2: -229
A3: 2022-01-08 | B3: CC00002 | C3: Facebook Ads | D3: Other | E3: Debit | F3: 444 | G3: 673 | H3: 2022 | I3: 1 | J3: January | K3: 1 | L3: Saturday | M3: 5 | N3: TRUE | O3: FALSE | P3: -673
A4: 2022-01-10 | B4: CC00003 | C4: Payment to CC | D4: Payment | E4: Credit | F4: 428 | G4: 245 | H4: 2022 | I4: 1 | J4: January | K4: 1 | L4: Monday | M4: 0 | N4: FALSE | O4: TRUE | P4: -245
A5: 2022-01-15 | B5: CC00004 | C5: Utility Company | D5: Marketing | E5: Debit | F5: 360 | G5: 605 | H5: 2022 | I5: 1 | J5: January | K5: 1 | L5: Saturday | M5: 5 | N5: TRUE | O5: FALSE | P5: -605
A6: 2022-01-22 | B6: CC00005 | C6: Local Print Shop | D6: Marketing | E6: Debit | F6: 539 | G6: 1144 | H6: 2022 | I6: 1 | J6: January | K6: 1 | L6: Saturday | M6: 5 | N6: TRUE | O6: FALSE | P6: -1144
A7: 2022-01-24 | B7: CC00006 | C7: Payment to CC | D7: Payment | E7: Credit | F7: 486 | G7: 658 | H7: 2022 | I7: 1 | J7: January | K7: 1 | L7: Monday | M7: 0 | N7: FALSE | O7: TRUE | P7: -658
A8: 2022-01-29 | B8: CC00007 | C8: Coffee Supplier | D8: Utilities | E8: Debit | F8: 494 | G8: 1152 | H8: 2022 | I8: 1 | J8: January | K8: 1 | L8: Saturday | M8: 5 | N8: TRUE | O8: FALSE | P8: -1152
A9: 2022-02-05 | B9: CC00008 | C9: Coffee Supplier | D9: Marketing | E9: Debit | F9: 179 | G9: 1331 | H9: 2022 | I9: 2 | J9: February | K9: 1 | L9: Saturday | M9: 5 | N9: TRUE | O9: FALSE | P9: -1331
A10: 2022-02-12 | B10: CC00009 | C10: Facebook Ads | D10: Marketing | E10: Debit | F10: 449 | G10: 1780 | H10: 2022 | I10: 2 | J10: February | K10: 1 | L10: Saturday | M10: 5 | N10: TRUE | O10: FALSE | P10: -1780
A11: 2022-02-19 | B11: CC00010 | C11: Utility Company | D11: Other | E11: Debit | F11: 363 | G11: 2143 | H11: 2022 | I11: 2 | J11: February | K11: 1 | L11: Saturday | M11: 5 | N11: TRUE | O11: FALSE | P11: -2143
A12: 2022-02-26 | B12: CC00011 | C12: Coffee Supplier | D12: Other | E12: Debit | F12: 163 | G12: 2306 | H12: 2022 | I12: 2 | J12: February | K12: 1 | L12: Saturday | M12: 5 | N12: TRUE | O12: FALSE | P12: -2306
A13: 2022-03-05 | B13: CC00012 | C13: Facebook Ads | D13: Utilities | E13: Debit | F13: 206 | G13: 2512 | H13: 2022 | I13: 3 | J13: March | K13: 1 | L13: Saturday | M13: 5 | N13: TRUE | O13: FALSE | P13: -2512
... A134: 2023-12-30 | B134: CC00133 | C134: Local Print Shop | D134: Utilities | E134: Debit | F134: 589 | G134: 21651 | H134: 2023 | I134: 12 | J134: December | K134: 4 | L134: Saturday | M134: 5 | N134: TRUE | O134: FALSE | P134: -21651

Sheet Статистика
A1: Показатель | B1: Значение
A2: 🏦 ОСНОВНОЙ СЧЕТ
A3: Всего поступлений | B3: $ 582,807.00
A4: Всего расходов | B4: $ 43,199.00
A5: Чистый денежный поток | B5: $ 539,608.00
A6: Количество транзакций | B6: 877
A7: 💳 КРЕДИТНАЯ КАРТА
A8: Всего списаний | B8: $ 36,797.00
A9: Всего платежей | B9: $ 15,146.00
A10: Чистое использование | B10: $ 21,651.00
A11: Количество транзакций | B11: 133
A12: 👤 ЗАРПЛАТЫ
A13: Всего зарплат | B13: $ 159,854.00
A14: Сотрудники | B14: $ 132,001.00
A15: Контракторы | B15: $ 27,853.00
A16: Количество записей | B16: 92
A17: 📊 КЛЮЧЕВЫЕ МЕТРИКИ
A18: Зарплаты / Доходы | B18: 27.43%
A19: Расходы / Доходы | B19: 7.41%
